<?xml version="1.0" ?>
<robot xmlns:xacro="http://www.ros.org/wiki/xacro">
    <link name="arm_outer">
        <inertial>
            <mass value="0.12" />
            <inertia ixx="1.29032e-05" ixy="0" ixz="0" iyy="0.0005127016" iyz="0" izz="0.0005127016" />
        </inertial>
        <collision>
            <origin xyz="0.1125 0 -0.0127" rpy="0 0 0" />
            <geometry>
                <box size="0.225 0.0254 0.0254" />
            </geometry>
        </collision>
        <visual>
            <material name="Blue" />
            <origin xyz="0.1125 0 -0.0127" rpy="0 0 0" />
            <geometry>
                <box size="0.225 0.0254 0.0254" />
            </geometry>
        </visual>
    </link>

    <link name="grip_spin">
        <inertial>
            <mass value="0.05" />
            <inertia ixx="4.94791666667e-05" ixy="0" ixz="0" iyy="4.94791666667e-05" iyz="0" izz="1.5625e-05" />
        </inertial>
        <collision>
            <origin xyz="0 0 -0.05" rpy="0 0 0" />
            <geometry>
                <cylinder radius="0.025" length="0.1" />
            </geometry>
        </collision>
        <visual>
            <material name="Blue" />
            <origin xyz="0 0 -0.05" rpy="0 0 0" />
            <geometry>
                <cylinder radius="0.025" length="0.1" />
            </geometry>
        </visual>
    </link>

    <joint name="arm_outer_to_grip_spin" type="continuous">
        <parent link="arm_outer" />
        <child link="grip_spin" />
        <origin xyz="0.225 0 -0.0127" rpy="0 0 0" />
        <axis xyz="0 0 1" />
    </joint>

    <joint name="arm_inner_to_arm_outer" type="continuous">
        <parent link="arm_inner" />
        <child link="arm_outer" />
        <origin xyz="0.217 0 -0.038" rpy="0 0 0" />
        <axis xyz="0 0 1" />
    </joint>

    <transmission name="arm_sping">
        <type>transmission_interface/SimpleTransmission</type>
        <joint name="arm_outer_to_grip_spin">
            <hardwareInterface>hardware_interface/EffortJointInterface</hardwareInterface>
        </joint>
        <actuator name="arm_spin_inner_motor">
            <hardwareInterface>hardware_interface/EffortJointInterface</hardwareInterface>
            <mechanicalReduction>1</mechanicalReduction>
        </actuator>
    </transmission>

    <transmission name="arm_outer_xy_trans">
        <type>transmission_interface/SimpleTransmission</type>
        <joint name="arm_inner_to_arm_outer">
            <hardwareInterface>hardware_interface/EffortJointInterface</hardwareInterface>
        </joint>
        <actuator name="arm_xy_outer_motor">
            <hardwareInterface>hardware_interface/EffortJointInterface</hardwareInterface>
            <mechanicalReduction>1</mechanicalReduction>
        </actuator>
    </transmission>
</robot>