<?xml version="1.0" ?>
<robot xmlns:xacro="http://www.ros.org/wiki/xacro">
    <xacro:macro name="arm_z_pole" params="suffix x">
        <link name="arm_z_pole_${suffix}">
            <inertial>
                <mass value="0.22"/>
                <inertia ixx="0.0183532929708" ixy="0" ixz="0" iyy="0.0183532929708" iyz="0" izz="3.9919275e-05" />
            </inertial>
            <visual>
                <origin xyz="0 0 0.485" rpy="0 0 0"/>
                <material name="Red"/>
                <geometry>
                    <cylinder length="0.97" radius="0.01905"/>
                </geometry>
            </visual>
            <collision>
                <origin xyz="0 0 0.485" rpy="0 0 0"/>
                <geometry>
                    <cylinder length="0.97" radius="0.01905"/>
                </geometry>
            </collision>
        </link>

        <joint name="base_link_to_arm_z_pole_${suffix}" type="fixed">
            <parent link="base_link" />
            <child link="arm_z_pole_${suffix}" />
            <origin xyz="${x} 0 0.25" />
        </joint>
    </xacro:macro>

    <xacro:arm_z_pole x="0.3" suffix="back" />
    <xacro:arm_z_pole x="0.45" suffix="front" />

    <link name="arm_z_pole_endcap">
        <inertial>
            <mass value="0.39" />
            <inertia ixx="0.0001105" ixy="0" ixz="0" iyy="0.00132925" iyz="0" izz="0.00138125" />
        </inertial>
        <visual>
            <origin xyz="0.075 0 0.03" rpy="0 0 0" />
            <material name="Yellow" />
            <geometry>
                <box size="0.2 0.05 0.03" />
            </geometry>
        </visual>
        <collision>
            <origin xyz="0.075 0 0.03" rpy="0 0 0" />
            <geometry>
                <box size="0.2 0.05 0.03" />
            </geometry>
        </collision>
    </link>

    <joint name="arm_z_pole_to_arm_z_pole_endcap" type="fixed">
        <parent link="arm_z_pole_back" />
        <child link="arm_z_pole_endcap" />
        <origin xyz="0 0 0.97" />
    </joint>

    <link name="arm_slider_unit">
        <inertial>
            <mass value="1.26" />
            <inertia ixx="0.002625" ixy="0" ixz="0" iyy="0.021777" iyz="0" izz="0.019677" />
        </inertial>
        <visual>
            <material name="Green" />
            <origin xyz="0.19 0 0.075" rpy="0 0 0" />
            <geometry>
                <box size="0.43 0.05 0.15" />
            </geometry>
        </visual>
        <collision>
            <origin xyz="0.19 0 0.075" rpy="0 0 0" />
            <geometry>
                <box size="0.43 0.05 0.15" />
            </geometry>
        </collision>
    </link>

    <joint name="arm_slide_pole_to_arm_slider_unit" type="prismatic">
        <parent link="arm_z_pole_back" />
        <child link="arm_slider_unit" />
        <axis xyz="0 0 1" />
        <origin xyz="0 0 0" rpy="0 0 0" />
        <limit effort="2000" velocity="0.05" lower="0" upper="0.895" />
    </joint>

    <link name="gripper_base">
        <inertial>
            <mass value="0.3"/>
            <inertia ixx="0.0019375" ixy="0" ixz="0" iyy="0.0019375" iyz="0" izz="0.003375"/>
        </inertial>
        <visual>
            <material name="Yellow"/>
            <origin xyz="0 0 -0.05" rpy="0 0 0"/>
            <geometry>
                <cylinder length="0.1" radius="0.15"/>
            </geometry>
        </visual>
        <collision>
            <origin xyz="0 0 -0.05" rpy="0 0 0"/>
            <geometry>
                <cylinder length="0.1" radius="0.15"/>
            </geometry>
        </collision>
    </link>

    <joint name="arm_to_gripper" type="fixed">
        <parent link="arm_z_pole_front"/>
        <child link="gripper_base"/>
        <origin xyz="0 0 -0.05"/>
    </joint>

    <xacro:macro name="finger" params="suffix">
        <link name="gripper_finger_lower_${suffix}">
            <inertial>
                <mass value="0.08"/>
                <inertia ixx="0.000158" ixy="0" ixz="0" iyy="0.000158" iyz="0" izz="1.6e-05"/>
            </inertial>
            <visual>
                <origin xyz="0 0 -0.05" rpy="0 0 0"/>
                <material name="White"/>
                <geometry>
                    <cylinder radius="0.02" length="0.1"/>
                </geometry>
            </visual>
            <collision>
                <origin xyz="0 0 -0.075" rpy="0 0 0"/>
                <geometry>
                    <cylinder radius="0.02" length="0.1"/>
                </geometry>
            </collision>
        </link>
        <link name="gripper_finger_upper_${suffix}">
            <inertial>
                <mass value="0.08"/>
                <inertia ixx="0.000158" ixy="0" ixz="0" iyy="0.000158" iyz="0" izz="1.6e-05"/>
            </inertial>
            <visual>
                <origin xyz="0 0 -0.05" rpy="0 0 0"/>
                <material name="White"/>
                <geometry>
                    <cylinder radius="0.02" length="0.1"/>
                </geometry>
            </visual>
            <collision>
                <origin xyz="0 0 -0.075" rpy="0 0 0"/>
                <geometry>
                    <cylinder radius="0.02" length="0.1"/>
                </geometry>
            </collision>
        </link>

        <joint name="gripper_finger_link_${suffix}" type="fixed">
            <parent link="gripper_finger_lower_${suffix}"/>
            <child link="gripper_finger_upper_${suffix}"/>

            <origin xyz="0 0 -0.1" rpy="0 0.55 0"/>
        </joint>

    </xacro:macro>

    <xacro:finger suffix="front_left"/>
    <xacro:finger suffix="front_right"/>
    <xacro:finger suffix="back_left"/>
    <xacro:finger suffix="back_right"/>

    <joint name="gripper_base_to_finger_front_left" type="revolute">
        <parent link="gripper_base"/>
        <child link="gripper_finger_lower_front_left"/>
        <origin xyz="0.10605 -0.10605 -0.1" rpy="0 0 -0.7853"/>
        <axis xyz="0 -1 0"/>
        <limit effort="1000" velocity="0.4" lower="0" upper="0.55"/>
    </joint>

    <joint name="gripper_base_to_finger_front_right" type="revolute">
        <parent link="gripper_base"/>
        <child link="gripper_finger_lower_front_right"/>
        <origin xyz="0.10605 0.10605 -0.1" rpy="0 0 0.7853"/>
        <axis xyz="0 -1 0"/>
        <limit effort="1000" velocity="0.4" lower="0" upper="0.55"/>
    </joint>

    <joint name="gripper_base_to_finger_back_left" type="revolute">
        <parent link="gripper_base"/>
        <child link="gripper_finger_lower_back_left"/>
        <origin xyz="-0.10605 -0.10605 -0.1" rpy="0 0 -2.35619449"/>
        <axis xyz="0 -1 0"/>
        <limit effort="1000" velocity="0.4" lower="0" upper="0.55"/>
    </joint>

    <joint name="gripper_base_to_finger_back_right" type="revolute">
        <parent link="gripper_base"/>
        <child link="gripper_finger_lower_back_right"/>
        <origin xyz="-0.10605 0.10605 -0.1" rpy="0 0 2.35619449"/>
        <axis xyz="0 -1 0"/>
        <limit effort="1000" velocity="0.4" lower="0" upper="0.55"/>
    </joint>

    <transmission name="arm_post_rotate_trans">
        <type>transmission_interface/SimpleTransmission</type>
        <joint name="arm_base_to_post">
            <hardwareInterface>hardware_interface/EffortJointInterface</hardwareInterface>
        </joint>
        <actuator name="arm_rotate_motor">
            <hardwareInterface>hardware_interface/EffortJointInterface</hardwareInterface>
            <mechanicalReduction>1</mechanicalReduction>
        </actuator>
    </transmission>

    <transmission name="arm_xy_trans">
        <type>transmission_interface/SimpleTransmission</type>
        <joint name="arm_inner_to_outer_xy">
            <hardwareInterface>hardware_interface/EffortJointInterface</hardwareInterface>
        </joint>
        <actuator name="arm_xy_motor">
            <hardwareInterface>hardware_interface/EffortJointInterface</hardwareInterface>
            <mechanicalReduction>1</mechanicalReduction>
        </actuator>
    </transmission>

    <transmission name="arm_slide_trans">
        <type>transmission_inteface/SimpleTransmission</type>
        <joint name="arm_z_slide">
            <hardwareInterface>hardware_interface/EffortJointInterface</hardwareInterface>
        </joint>
        <actuator name="arm_slide_motor">
            <hardwareInterface>hardware_interface/EffortJointInterface</hardwareInterface>
            <mechanicalReduction>5</mechanicalReduction>
        </actuator>
    </transmission>

    <transmission name="arm_g_rotz_trans">
        <type>transmission_interface/SimpleTransmission</type>
        <joint name="arm_gripper_rot_z">
            <hardwareInterface>hardware_interface/EffortJointInterface</hardwareInterface>
        </joint>
        <actuator name="arm_grip_rot_z_motor">
            <hardwareInterface>hardware_interface/EffortJointInterface</hardwareInterface>
            <mechanicalReduction>1</mechanicalReduction>
        </actuator>
    </transmission>

    <transmission name="arm_g_roty_trans">
        <type>transmission_interface/SimpleTransmission</type>
        <joint name="arm_gripper_rot_y">
            <hardwareInterface>hardware_interface/EffortJointInterface</hardwareInterface>
        </joint>
        <actuator name="arm_grip_rot_y_motor">
            <hardwareInterface>hardware_interface/EffortJointInterface</hardwareInterface>
            <mechanicalReduction>1</mechanicalReduction>
        </actuator>
    </transmission>

    <transmission name="grip_finger_front_left_trans">
        <type>transmission_interface/SimpleTransmission</type>
        <joint name="gripper_base_to_finger_front_left">
            <hardwareInterface>hardware_interface/EffortJointInterface</hardwareInterface>
        </joint>
        <actuator name="gripper_base_to_finger_front_left_motor">
            <hardwareInterface>hardware_interface/EffortJointInterface</hardwareInterface>
            <mechanicalReduction>1</mechanicalReduction>
        </actuator>
    </transmission>

    <transmission name="grip_finger_front_right_trans">
        <type>transmission_interface/SimpleTransmission</type>
        <joint name="gripper_base_to_finger_front_right">
            <hardwareInterface>hardware_interface/EffortJointInterface</hardwareInterface>
        </joint>
        <actuator name="gripper_base_to_finger_front_right_motor">
            <hardwareInterface>hardware_interface/EffortJointInterface</hardwareInterface>
            <mechanicalReduction>1</mechanicalReduction>
        </actuator>
    </transmission>

    <transmission name="grip_finger_back_left_trans">
        <type>transmission_interface/SimpleTransmission</type>
        <joint name="gripper_base_to_finger_back_left">
            <hardwareInterface>hardware_interface/EffortJointInterface</hardwareInterface>
        </joint>
        <actuator name="gripper_base_to_finger_back_left_motor">
            <hardwareInterface>hardware_interface/EffortJointInterface</hardwareInterface>
            <mechanicalReduction>1</mechanicalReduction>
        </actuator>
    </transmission>

    <transmission name="grip_finger_back_right_trans">
        <type>transmission_interface/SimpleTransmission</type>
        <joint name="gripper_base_to_finger_back_right">
            <hardwareInterface>hardware_interface/EffortJointInterface</hardwareInterface>
        </joint>
        <actuator name="gripper_base_to_finger_back_right_motor">
            <hardwareInterface>hardware_interface/EffortJointInterface</hardwareInterface>
            <mechanicalReduction>1</mechanicalReduction>
        </actuator>
    </transmission>

</robot>