<?xml version="1.0" ?>
<robot xmlns:xacro="http://www.ros.org/wiki/xacro">
    <xacro:macro name="wheel" params="suffix attach side">
        <link name="wheel_leg_${suffix}">
            <inertial>
                <mass value="0.4" />
                <inertia ixx="0.004" ixy="0" ixz="0" iyy="0.004" iyz="0" izz="0.002" />
            </inertial>
            <visual>
                <origin xyz="0 0 -0.15" rpy="0 0 0" />
                <material name="Red" />
                <geometry>
                    <cylinder radius="0.1" length="0.3" />
                </geometry>
            </visual>
            <collision>
                <origin xyz="0 0 -0.15" rpy="0 0 0" />
                <geometry>
                    <cylinder radius="0.1" length="0.3" />
                </geometry>
            </collision>
        </link>
        <joint name="base_to_leg_${suffix}" type="fixed">
            <origin xyz="${attach}" rpy="0 0 0" />
            <parent link="base_link" />
            <child link="wheel_leg_${suffix}" />
        </joint>
        <link name="wheel_${suffix}">
            <inertial>
                <mass value="0.25" />
                <inertia ixx="0.00333333333333" ixy="0" ixz="0" iyy="0.005" iyz="0" izz="0.00333333333333" />
            </inertial>
            <visual>
                <origin xyz="0 0 0" rpy="1.5708 0 0" />
                <material name="White" />
                <geometry>
                    <cylinder radius="0.1" length="0.1" />
                </geometry>
            </visual>
            <collision>
                <origin xyz="0 0 0" rpy="1.5708 0 0" />
                <geometry>
                    <cylinder radius="0.1" length="0.1" />
                </geometry>
            </collision>
        </link>
        <joint name="leg_to_wheel_${suffix}" type="continuous">
            <origin xyz="0 ${side * 0.1} -0.3" rpy="0 0 0" />
            <parent link="wheel_leg_${suffix}" />
            <child link="wheel_${suffix}" />
            <axis xyz="0 1 0" />
            <!-- dynamics damping="0.015" friction="0.02" / -->
        </joint>

        <gazebo reference="wheel_leg_${suffix}">
            <material>Gazebo/Red</material>
        </gazebo>

        <gazebo reference="wheel_${suffix}">
            <collision name="wheel_${suffix}_collision">
                <surface>
                    <friction>
                        <torsional>
                            <coefficient>0.6</coefficient>
                            <use_patch_radius>true</use_patch_radius>
                            <patch_radius>0.1</patch_radius>
                        </torsional>
                    </friction>
                </surface>
            </collision>
        </gazebo>

        <transmission name="wheel_transmission_${suffix}">
            <type>transmission_interface/SimpleTransmission</type>
            <joint name="leg_to_wheel_${suffix}">
                <hardwareInterface>hardware_interface/VelocityJointInterface</hardwareInterface>
            </joint>
            <actuator name="drive_motor_${suffix}">
                <hardwareInterface>hardware_interface/VelocityJointInterface</hardwareInterface>
                <mechanicalReduction>1</mechanicalReduction>
            </actuator>
        </transmission>
    </xacro:macro>
</robot>